<?xml version="1.0" ?>
<!-- =================================================================================== -->
<!-- |    This document was autogenerated by xacro from src/robot_description/urdf/custom_6axis_test.urdf.xacro | -->
<!-- |    EDITING THIS FILE BY HAND IS NOT RECOMMENDED                                 | -->
<!-- =================================================================================== -->
<robot name="industrial_6dof">
  <!-- Materials -->
  <material name="industrial_orange">
    <color rgba="1.0 0.4 0.0 1.0"/>
  </material>
  <material name="industrial_dark">
    <color rgba="0.2 0.2 0.22 1.0"/>
  </material>
  <material name="industrial_silver">
    <color rgba="0.75 0.75 0.75 1.0"/>
  </material>
  <!-- ======================== CONSTANTS ======================== -->
  <!-- pi is natively built into newer xacro versions -->
  <!-- ======================== LINKS & JOINTS ======================== -->
  <!-- Dummy root link to prevent KDL & Gazebo root inertia errors -->
  <link name="world"/>
  <joint name="fixed_base_joint" type="fixed">
    <parent link="world"/>
    <child link="base_link"/>
    <origin rpy="0 0 0" xyz="0 0 0"/>
  </joint>
  <!-- Base Link (Pedestal) -->
  <link name="base_link">
    <visual>
      <geometry>
        <cylinder length="0.15" radius="0.18"/>
      </geometry>
      <origin rpy="0 0 0" xyz="0 0 0.075"/>
      <material name="industrial_dark"/>
    </visual>
    <collision>
      <geometry>
        <cylinder length="0.15" radius="0.18"/>
      </geometry>
      <origin rpy="0 0 0" xyz="0 0 0.075"/>
    </collision>
    <inertial>
      <mass value="15.0"/>
      <origin rpy="0 0 0" xyz="0 0 0.075"/>
      <inertia ixx="0.2" ixy="0.0" ixz="0.0" iyy="0.2" iyz="0.0" izz="0.4"/>
    </inertial>
  </link>
  <!-- Link 1 (Shoulder Pan) -->
  <link name="link_1">
    <visual>
      <geometry>
        <cylinder length="0.25" radius="0.14"/>
      </geometry>
      <origin rpy="0 0 0" xyz="0 0 0.125"/>
      <material name="industrial_orange"/>
    </visual>
    <collision>
      <geometry>
        <cylinder length="0.25" radius="0.14"/>
      </geometry>
      <origin rpy="0 0 0" xyz="0 0 0.125"/>
    </collision>
    <inertial>
      <mass value="12.0"/>
      <origin rpy="0 0 0" xyz="0 0 0.125"/>
      <inertia ixx="0.15" ixy="0.0" ixz="0.0" iyy="0.15" iyz="0.0" izz="0.1"/>
    </inertial>
  </link>
  <joint name="joint_1" type="revolute">
    <parent link="base_link"/>
    <child link="link_1"/>
    <origin rpy="0 0 0" xyz="0 0 0.15"/>
    <axis xyz="0 0 1"/>
    <limit effort="300" lower="-2.96" upper="2.96" velocity="2.1"/>
    <dynamics damping="10.0" friction="5.0"/>
  </joint>
  <!-- Link 2 (Shoulder Lift / Upper Arm) -->
  <link name="link_2">
    <visual>
      <!-- Main Arm -->
      <geometry>
        <cylinder length="0.45" radius="0.09"/>
      </geometry>
      <origin rpy="0 0 0" xyz="0 0 0.225"/>
      <material name="industrial_orange"/>
    </visual>
    <visual>
      <!-- Shoulder Joint Cap -->
      <geometry>
        <cylinder length="0.16" radius="0.11"/>
      </geometry>
      <origin rpy="1.5707963267948966 0 0" xyz="0 0 0"/>
      <material name="industrial_dark"/>
    </visual>
    <collision>
      <geometry>
        <cylinder length="0.45" radius="0.09"/>
      </geometry>
      <origin rpy="0 0 0" xyz="0 0 0.225"/>
    </collision>
    <inertial>
      <mass value="10.0"/>
      <origin rpy="0 0 0" xyz="0 0 0.225"/>
      <inertia ixx="0.3" ixy="0.0" ixz="0.0" iyy="0.3" iyz="0.0" izz="0.05"/>
    </inertial>
  </link>
  <joint name="joint_2" type="revolute">
    <parent link="link_1"/>
    <child link="link_2"/>
    <origin rpy="1.5707963267948966 0 0" xyz="0 0.05 0.25"/>
    <!-- Rotated so Link 2 extends outwards -->
    <axis xyz="0 0 1"/>
    <limit effort="300" lower="-2.35" upper="2.35" velocity="2.1"/>
    <dynamics damping="10.0" friction="5.0"/>
  </joint>
  <!-- Link 3 (Elbow) -->
  <link name="link_3">
    <visual>
      <!-- Forearm Base -->
      <geometry>
        <cylinder length="0.15" radius="0.08"/>
      </geometry>
      <origin rpy="0 0 0" xyz="0 0 0.075"/>
      <material name="industrial_orange"/>
    </visual>
    <visual>
      <!-- Elbow Joint Cap -->
      <geometry>
        <cylinder length="0.14" radius="0.095"/>
      </geometry>
      <origin rpy="1.5707963267948966 0 0" xyz="0 0 0"/>
      <material name="industrial_dark"/>
    </visual>
    <collision>
      <geometry>
        <cylinder length="0.15" radius="0.08"/>
      </geometry>
      <origin rpy="0 0 0" xyz="0 0 0.075"/>
    </collision>
    <inertial>
      <mass value="8.0"/>
      <origin rpy="0 0 0" xyz="0 0 0.075"/>
      <inertia ixx="0.05" ixy="0.0" ixz="0.0" iyy="0.05" iyz="0.0" izz="0.03"/>
    </inertial>
  </link>
  <joint name="joint_3" type="revolute">
    <parent link="link_2"/>
    <child link="link_3"/>
    <origin rpy="0 0 0" xyz="0 0 0.45"/>
    <axis xyz="0 0 1"/>
    <limit effort="150" lower="-2.61" upper="2.61" velocity="2.5"/>
    <dynamics damping="5.0" friction="2.0"/>
  </joint>
  <!-- Link 4 (Forearm Roll) -->
  <link name="link_4">
    <visual>
      <geometry>
        <cylinder length="0.35" radius="0.06"/>
      </geometry>
      <origin rpy="0 0 0" xyz="0 0 0.175"/>
      <material name="industrial_silver"/>
    </visual>
    <collision>
      <geometry>
        <cylinder length="0.35" radius="0.06"/>
      </geometry>
      <origin rpy="0 0 0" xyz="0 0 0.175"/>
    </collision>
    <inertial>
      <mass value="5.0"/>
      <origin rpy="0 0 0" xyz="0 0 0.175"/>
      <inertia ixx="0.1" ixy="0.0" ixz="0.0" iyy="0.1" iyz="0.0" izz="0.02"/>
    </inertial>
  </link>
  <joint name="joint_4" type="revolute">
    <parent link="link_3"/>
    <child link="link_4"/>
    <origin rpy="-1.5707963267948966 0 0" xyz="0 -0.05 0.15"/>
    <axis xyz="0 0 1"/>
    <limit effort="100" lower="-3.14" upper="3.14" velocity="3.0"/>
    <dynamics damping="3.0" friction="1.0"/>
  </joint>
  <!-- Link 5 (Wrist Pitch) -->
  <link name="link_5">
    <visual>
      <geometry>
        <cylinder length="0.12" radius="0.05"/>
      </geometry>
      <origin rpy="0 0 0" xyz="0 0 0.06"/>
      <material name="industrial_dark"/>
    </visual>
    <visual>
      <!-- Wrist Joint Cap -->
      <geometry>
        <cylinder length="0.1" radius="0.06"/>
      </geometry>
      <origin rpy="1.5707963267948966 0 0" xyz="0 0 0"/>
      <material name="industrial_silver"/>
    </visual>
    <collision>
      <geometry>
        <cylinder length="0.12" radius="0.05"/>
      </geometry>
      <origin rpy="0 0 0" xyz="0 0 0.06"/>
    </collision>
    <inertial>
      <mass value="2.0"/>
      <origin rpy="0 0 0" xyz="0 0 0.06"/>
      <inertia ixx="0.01" ixy="0.0" ixz="0.0" iyy="0.01" iyz="0.0" izz="0.01"/>
    </inertial>
  </link>
  <joint name="joint_5" type="revolute">
    <parent link="link_4"/>
    <child link="link_5"/>
    <origin rpy="1.5707963267948966 0 0" xyz="0 0 0.35"/>
    <axis xyz="0 0 1"/>
    <limit effort="50" lower="-2.09" upper="2.09" velocity="3.0"/>
    <dynamics damping="1.0" friction="0.5"/>
  </joint>
  <!-- Link 6 (Wrist Roll / Flange) -->
  <link name="link_6">
    <visual>
      <geometry>
        <cylinder length="0.02" radius="0.045"/>
      </geometry>
      <origin rpy="0 0 0" xyz="0 0 0.01"/>
      <material name="industrial_silver"/>
    </visual>
    <collision>
      <geometry>
        <cylinder length="0.02" radius="0.045"/>
      </geometry>
      <origin rpy="0 0 0" xyz="0 0 0.01"/>
    </collision>
    <inertial>
      <mass value="0.5"/>
      <origin rpy="0 0 0" xyz="0 0 0.01"/>
      <inertia ixx="0.001" ixy="0.0" ixz="0.0" iyy="0.001" iyz="0.0" izz="0.001"/>
    </inertial>
  </link>
  <joint name="joint_6" type="revolute">
    <parent link="link_5"/>
    <child link="link_6"/>
    <origin rpy="-1.5707963267948966 0 0" xyz="0 -0.05 0.12"/>
    <axis xyz="0 0 1"/>
    <limit effort="20" lower="-6.28" upper="6.28" velocity="4.0"/>
    <dynamics damping="0.5" friction="0.1"/>
  </joint>
  <!-- Tool0 -->
  <link name="tool0"/>
  <joint name="joint_6-tool0" type="fixed">
    <parent link="link_6"/>
    <child link="tool0"/>
    <origin rpy="0 0 0" xyz="0 0 0.02"/>
  </joint>
  <!-- ======================== GAZEBO COLORS ======================== -->
  <gazebo reference="base_link">
    <material>Gazebo/DarkGrey</material>
  </gazebo>
  <gazebo reference="link_1">
    <material>Gazebo/Orange</material>
  </gazebo>
  <gazebo reference="link_2">
    <material>Gazebo/Orange</material>
  </gazebo>
  <gazebo reference="link_3">
    <material>Gazebo/Orange</material>
  </gazebo>
  <gazebo reference="link_4">
    <material>Gazebo/Grey</material>
  </gazebo>
  <gazebo reference="link_5">
    <material>Gazebo/DarkGrey</material>
  </gazebo>
  <gazebo reference="link_6">
    <material>Gazebo/Grey</material>
  </gazebo>
  <!-- ======================== ROS 2 CONTROL ======================== -->
  <ros2_control name="GazeboSystem" type="system">
    <hardware>
      <plugin>gz_ros2_control/GazeboSimSystem</plugin>
    </hardware>
    <joint name="joint_1">
      <command_interface name="position"/>
      <state_interface name="position"/>
      <state_interface name="velocity"/>
    </joint>
    <joint name="joint_2">
      <command_interface name="position"/>
      <state_interface name="position"/>
      <state_interface name="velocity"/>
    </joint>
    <joint name="joint_3">
      <command_interface name="position"/>
      <state_interface name="position"/>
      <state_interface name="velocity"/>
    </joint>
    <joint name="joint_4">
      <command_interface name="position"/>
      <state_interface name="position"/>
      <state_interface name="velocity"/>
    </joint>
    <joint name="joint_5">
      <command_interface name="position"/>
      <state_interface name="position"/>
      <state_interface name="velocity"/>
    </joint>
    <joint name="joint_6">
      <command_interface name="position"/>
      <state_interface name="position"/>
      <state_interface name="velocity"/>
    </joint>
  </ros2_control>
  <gazebo>
    <plugin filename="gz_ros2_control-system" name="ign_ros2_control::IgnitionROS2ControlPlugin">
      <parameters>/mnt/d/Projects/ROBOT/6-Axis-robot-ROS2-control-movet-gazebo-/install/robot_gazebo/share/robot_gazebo/config/gazebo_controllers.yaml</parameters>
    </plugin>
  </gazebo>
</robot>
