<?xml version="1.0" encoding="UTF-8"?>
<robot name="6axis_arm">

  <!-- ============================================= -->
  <!--  BASE LINK (fixed to world)                   -->
  <!-- ============================================= -->
  <link name="base_link">
    <visual>
      <origin xyz="0 0 0.025" rpy="0 0 0"/>
      <geometry>
        <cylinder radius="0.12" length="0.05"/>
      </geometry>
    </visual>
  </link>

  <!-- ============================================= -->
  <!--  JOINT 1: Base Rotation (Yaw)                 -->
  <!-- ============================================= -->
  <joint name="joint1" type="revolute">
    <parent link="base_link"/>
    <child link="link1"/>
    <origin xyz="0 0 0.05" rpy="0 0 0"/>
    <axis xyz="0 0 1"/>
    <limit lower="-3.14159" upper="3.14159"/>
  </joint>

  <link name="link1">
    <visual>
      <origin xyz="0 0 0.1" rpy="0 0 0"/>
      <geometry>
        <cylinder radius="0.08" length="0.2"/>
      </geometry>
    </visual>
  </link>

  <!-- ============================================= -->
  <!--  JOINT 2: Shoulder (Pitch)                    -->
  <!-- ============================================= -->
  <joint name="joint2" type="revolute">
    <parent link="link1"/>
    <child link="link2"/>
    <origin xyz="0 0 0.2" rpy="0 0 0"/>
    <axis xyz="0 1 0"/>
    <limit lower="-2.268" upper="2.268"/>
  </joint>

  <link name="link2">
    <visual>
      <origin xyz="0 0 0.2" rpy="0 0 0"/>
      <geometry>
        <cylinder radius="0.06" length="0.4"/>
      </geometry>
    </visual>
  </link>

  <!-- ============================================= -->
  <!--  JOINT 3: Elbow (Pitch)                       -->
  <!-- ============================================= -->
  <joint name="joint3" type="revolute">
    <parent link="link2"/>
    <child link="link3"/>
    <origin xyz="0 0 0.4" rpy="0 0 0"/>
    <axis xyz="0 1 0"/>
    <limit lower="-2.268" upper="2.268"/>
  </joint>

  <link name="link3">
    <visual>
      <origin xyz="0 0 0.15" rpy="0 0 0"/>
      <geometry>
        <cylinder radius="0.05" length="0.3"/>
      </geometry>
    </visual>
  </link>

  <!-- ============================================= -->
  <!--  JOINT 4: Wrist 1 (Roll)                      -->
  <!-- ============================================= -->
  <joint name="joint4" type="revolute">
    <parent link="link3"/>
    <child link="link4"/>
    <origin xyz="0 0 0.3" rpy="0 0 0"/>
    <axis xyz="0 0 1"/>
    <limit lower="-3.14159" upper="3.14159"/>
  </joint>

  <link name="link4">
    <visual>
      <origin xyz="0 0 0.05" rpy="0 0 0"/>
      <geometry>
        <cylinder radius="0.04" length="0.1"/>
      </geometry>
    </visual>
  </link>

  <!-- ============================================= -->
  <!--  JOINT 5: Wrist 2 (Pitch)                     -->
  <!-- ============================================= -->
  <joint name="joint5" type="revolute">
    <parent link="link4"/>
    <child link="link5"/>
    <origin xyz="0 0 0.1" rpy="0 0 0"/>
    <axis xyz="0 1 0"/>
    <limit lower="-2.094" upper="2.094"/>
  </joint>

  <link name="link5">
    <visual>
      <origin xyz="0 0 0.04" rpy="0 0 0"/>
      <geometry>
        <cylinder radius="0.035" length="0.08"/>
      </geometry>
    </visual>
  </link>

  <!-- ============================================= -->
  <!--  JOINT 6: Wrist 3 / Tool Flange (Roll)        -->
  <!-- ============================================= -->
  <joint name="joint6" type="revolute">
    <parent link="link5"/>
    <child link="link6"/>
    <origin xyz="0 0 0.08" rpy="0 0 0"/>
    <axis xyz="0 0 1"/>
    <limit lower="-6.28318" upper="6.28318"/>
  </joint>

  <link name="link6">
    <visual>
      <origin xyz="0 0 0.02" rpy="0 0 0"/>
      <geometry>
        <box size="0.06 0.06 0.04"/>
      </geometry>
    </visual>
  </link>

</robot>
